Workbook

Sheet Portfolio Input
A1: AI Moat Risk Analyzer — Portfolio Input
A2: Enter tickers in column A. Bloomberg BDP formulas auto-populate. Blue cells = manual inputs.
A3: HOW IT WORKS: Type ticker → Bloomberg populates financials → Score in Moat Scoring & BM Risk tabs → Dashboard auto-calculates.
A4: Ticker | B4: Company Name | C4: GICS Sector | D4: GICS Sub-Industry | E4: Price ($) | F4: Mkt Cap ($B) | G4: Beta | H4: Fwd P/E (x) | I4: ROIC (%) | J4: ROE (%) | K4: Gross Margin (%) | L4: Op. Margin (%) | M4: Net Margin (%) | N4: FCF Yield (%) | O4: D/E (x) | P4: Div Yield (%) | Q4: EV/EBITDA (x) | R4: P/B (x) | S4: R&D/Rev (%) | T4: 5yr Rev CAGR (%) | U4: WACC Est (%)
A5: AAPL | B5: =IF(A5="","",_xll.BDP(A5&" US Equity","NAME")) -> APPLE INC | C5: =IF(A5="","",_xll.BDP(A5&" US Equity","GICS_SECTOR_NAME")) -> Information Technology | D5: =IF(A5="","",_xll.BDP(A5&" US Equity","GICS_SUB_INDUSTRY_NAME")) -> Technology Hardware, Storage & | E5: =IF(A5="","",_xll.BDP(A5&" US Equity","PX_LAST")) -> 259.445 | F5: =IF(A5="","",_xll.BDP(A5&" US Equity","CUR_MKT_CAP")/1000000000) -> 3808.9484 | G5: =IF(A5="","",_xll.BDP(A5&" US Equity","BETA_RAW_OVERRIDABLE")) -> 1.1099219 | H5: =IF(A5="","",_xll.BDP(A5&" US Equity","BEST_PE_RATIO")) -> 30.052705 | I5: =IF(A5="","",_xll.BDP(A5&" US Equity","RETURN_ON_INV_CAPITAL")) -> 68.788493 | J5: =IF(A5="","",_xll.BDP(A5&" US Equity","RETURN_COM_EQY")) -> 152.02132 | K5: =IF(A5="","",_xll.BDP(A5&" US Equity","GROSS_MARGIN")) -> 46.905164 | L5: =IF(A5="","",_xll.BDP(A5&" US Equity","OPER_MARGIN")) -> 31.9708 | M5: =IF(A5="","",_xll.BDP(A5&" US Equity","NET_INCOME_MARGIN")) -> #N/A Invalid Field | N5: =IF(A5="","",_xll.BDP(A5&" US Equity","FREE_CASH_FLOW_YIELD")) -> 3.2043212 | O5: =IF(A5="","",_xll.BDP(A5&" US Equity","TOT_DEBT_TO_TOT_EQY")) -> 152.41073 | P5: =IF(A5="","",_xll.BDP(A5&" US Equity","EQY_DVD_YLD_IND")) -> 0.40085566 | Q5: =IF(A5="","",_xll.BDP(A5&" US Equity","BEST_CUR_EV_TO_EBITDA")) -> 22.607475 | R5: =IF(A5="","",_xll.BDP(A5&" US Equity","PX_TO_BOOK_RATIO")) -> 43.25369 | S5: =IF(A5="","",_xll.BDP(A5&" US Equity","RESEARCH_AND_DEV_TO_REVENUE")) -> #N/A Invalid Field | T5: =IF(A5="","",_xll.BDP(A5&" US Equity","REVENUE_5YR_CAGR")) -> #N/A Invalid Field | U5: =IF(A5="","",0.045+G5*0.05) -> 0.1004961
A6: MSFT | B6: =IF(A6="","",_xll.BDP(A6&" US Equity","NAME")) -> MICROSOFT CORP | C6: =IF(A6="","",_xll.BDP(A6&" US Equity","GICS_SECTOR_NAME")) -> Information Technology | D6: =IF(A6="","",_xll.BDP(A6&" US Equity","GICS_SUB_INDUSTRY_NAME")) -> Systems Software | E6: =IF(A6="","",_xll.BDP(A6&" US Equity","PX_LAST")) -> 402.795 | F6: =IF(A6="","",_xll.BDP(A6&" US Equity","CUR_MKT_CAP")/1000000000) -> 2991.0063 | G6: =IF(A6="","",_xll.BDP(A6&" US Equity","BETA_RAW_OVERRIDABLE")) -> 1.0233857 | H6: =IF(A6="","",_xll.BDP(A6&" US Equity","BEST_PE_RATIO")) -> 22.88608 | I6: =IF(A6="","",_xll.BDP(A6&" US Equity","RETURN_ON_INV_CAPITAL")) -> 25.012015 | J6: =IF(A6="","",_xll.BDP(A6&" US Equity","RETURN_COM_EQY")) -> 34.390761 | K6: =IF(A6="","",_xll.BDP(A6&" US Equity","GROSS_MARGIN")) -> 68.823742 | L6: =IF(A6="","",_xll.BDP(A6&" US Equity","OPER_MARGIN")) -> 45.621956 | M6: =IF(A6="","",_xll.BDP(A6&" US Equity","NET_INCOME_MARGIN")) -> #N/A Invalid Field | N6: =IF(A6="","",_xll.BDP(A6&" US Equity","FREE_CASH_FLOW_YIELD")) -> 2.585669 | O6: =IF(A6="","",_xll.BDP(A6&" US Equity","TOT_DEBT_TO_TOT_EQY")) -> 32.661094 | P6: =IF(A6="","",_xll.BDP(A6&" US Equity","EQY_DVD_YLD_IND")) -> 0.90368552 | Q6: =IF(A6="","",_xll.BDP(A6&" US Equity","BEST_CUR_EV_TO_EBITDA")) -> 14.170161 | R6: =IF(A6="","",_xll.BDP(A6&" US Equity","PX_TO_BOOK_RATIO")) -> 7.6555527 | S6: =IF(A6="","",_xll.BDP(A6&" US Equity","RESEARCH_AND_DEV_TO_REVENUE")) -> #N/A Invalid Field | T6: =IF(A6="","",_xll.BDP(A6&" US Equity","REVENUE_5YR_CAGR")) -> #N/A Invalid Field | U6: =IF(A6="","",0.045+G6*0.05) -> 0.096169286
A7: GOOGL | B7: =IF(A7="","",_xll.BDP(A7&" US Equity","NAME")) -> ALPHABET INC-CL A | C7: =IF(A7="","",_xll.BDP(A7&" US Equity","GICS_SECTOR_NAME")) -> Communication Services | D7: =IF(A7="","",_xll.BDP(A7&" US Equity","GICS_SUB_INDUSTRY_NAME")) -> Interactive Media & Services | E7: =IF(A7="","",_xll.BDP(A7&" US Equity","PX_LAST")) -> 306.735 | F7: =IF(A7="","",_xll.BDP(A7&" US Equity","CUR_MKT_CAP")/1000000000) -> 3712.828 | G7: =IF(A7="","",_xll.BDP(A7&" US Equity","BETA_RAW_OVERRIDABLE")) -> 1.065303 | H7: =IF(A7="","",_xll.BDP(A7&" US Equity","BEST_PE_RATIO")) -> 25.162838 | I7: =IF(A7="","",_xll.BDP(A7&" US Equity","RETURN_ON_INV_CAPITAL")) -> 25.130867 | J7: =IF(A7="","",_xll.BDP(A7&" US Equity","RETURN_COM_EQY")) -> 35.704782 | K7: =IF(A7="","",_xll.BDP(A7&" US Equity","GROSS_MARGIN")) -> 59.652315 | L7: =IF(A7="","",_xll.BDP(A7&" US Equity","OPER_MARGIN")) -> 32.032639 | M7: =IF(A7="","",_xll.BDP(A7&" US Equity","NET_INCOME_MARGIN")) -> #N/A Invalid Field | N7: =IF(A7="","",_xll.BDP(A7&" US Equity","FREE_CASH_FLOW_YIELD")) -> 1.9725348 | O7: =IF(A7="","",_xll.BDP(A7&" US Equity","TOT_DEBT_TO_TOT_EQY")) -> 15.156828 | P7: =IF(A7="","",_xll.BDP(A7&" US Equity","EQY_DVD_YLD_IND")) -> 0.27385201 | Q7: =IF(A7="","",_xll.BDP(A7&" US Equity","BEST_CUR_EV_TO_EBITDA")) -> 16.449676 | R7: =IF(A7="","",_xll.BDP(A7&" US Equity","PX_TO_BOOK_RATIO")) -> 9.0196402 | S7: =IF(A7="","",_xll.BDP(A7&" US Equity","RESEARCH_AND_DEV_TO_REVENUE")) -> #N/A Invalid Field | T7: =IF(A7="","",_xll.BDP(A7&" US Equity","REVENUE_5YR_CAGR")) -> #N/A Invalid Field | U7: =IF(A7="","",0.045+G7*0.05) -> 0.098265152
A8: NVDA | B8: =IF(A8="","",_xll.BDP(A8&" US Equity","NAME")) -> NVIDIA CORP | C8: =IF(A8="","",_xll.BDP(A8&" US Equity","GICS_SECTOR_NAME")) -> Information Technology | D8: =IF(A8="","",_xll.BDP(A8&" US Equity","GICS_SUB_INDUSTRY_NAME")) -> Semiconductors | E8: =IF(A8="","",_xll.BDP(A8&" US Equity","PX_LAST")) -> 184.0799 | F8: =IF(A8="","",_xll.BDP(A8&" US Equity","CUR_MKT_CAP")/1000000000) -> 4473.1416 | G8: =IF(A8="","",_xll.BDP(A8&" US Equity","BETA_RAW_OVERRIDABLE")) -> 2.2647578 | H8: =IF(A8="","",_xll.BDP(A8&" US Equity","BEST_PE_RATIO")) -> 26.136575 | I8: =IF(A8="","",_xll.BDP(A8&" US Equity","RETURN_ON_INV_CAPITAL")) -> 99.6596 | J8: =IF(A8="","",_xll.BDP(A8&" US Equity","RETURN_COM_EQY")) -> 107.35947 | K8: =IF(A8="","",_xll.BDP(A8&" US Equity","GROSS_MARGIN")) -> 74.988697 | L8: =IF(A8="","",_xll.BDP(A8&" US Equity","OPER_MARGIN")) -> 62.417527 | M8: =IF(A8="","",_xll.BDP(A8&" US Equity","NET_INCOME_MARGIN")) -> #N/A Invalid Field | N8: =IF(A8="","",_xll.BDP(A8&" US Equity","FREE_CASH_FLOW_YIELD")) -> 1.7211146 | O8: =IF(A8="","",_xll.BDP(A8&" US Equity","TOT_DEBT_TO_TOT_EQY")) -> 12.946412 | P8: =IF(A8="","",_xll.BDP(A8&" US Equity","EQY_DVD_YLD_IND")) -> 0.021729694 | Q8: =IF(A8="","",_xll.BDP(A8&" US Equity","BEST_CUR_EV_TO_EBITDA")) -> 20.715651 | R8: =IF(A8="","",_xll.BDP(A8&" US Equity","PX_TO_BOOK_RATIO")) -> 37.629729 | S8: =IF(A8="","",_xll.BDP(A8&" US Equity","RESEARCH_AND_DEV_TO_REVENUE")) -> #N/A Invalid Field | T8: =IF(A8="","",_xll.BDP(A8&" US Equity","REVENUE_5YR_CAGR")) -> #N/A Invalid Field | U8: =IF(A8="","",0.045+G8*0.05) -> 0.15823789
A9: AMZN | B9: =IF(A9="","",_xll.BDP(A9&" US Equity","NAME")) -> AMAZON.COM INC | C9: =IF(A9="","",_xll.BDP(A9&" US Equity","GICS_SECTOR_NAME")) -> Consumer Discretionary | D9: =IF(A9="","",_xll.BDP(A9&" US Equity","GICS_SUB_INDUSTRY_NAME")) -> Broadline Retail | E9: =IF(A9="","",_xll.BDP(A9&" US Equity","PX_LAST")) -> 200.51 | F9: =IF(A9="","",_xll.BDP(A9&" US Equity","CUR_MKT_CAP")/1000000000) -> 2152.459 | G9: =IF(A9="","",_xll.BDP(A9&" US Equity","BETA_RAW_OVERRIDABLE")) -> 1.4213262 | H9: =IF(A9="","",_xll.BDP(A9&" US Equity","BEST_PE_RATIO")) -> 21.155307 | I9: =IF(A9="","",_xll.BDP(A9&" US Equity","RETURN_ON_INV_CAPITAL")) -> 12.435293 | J9: =IF(A9="","",_xll.BDP(A9&" US Equity","RETURN_COM_EQY")) -> 22.285825 | K9: =IF(A9="","",_xll.BDP(A9&" US Equity","GROSS_MARGIN")) -> 50.285665 | L9: =IF(A9="","",_xll.BDP(A9&" US Equity","OPER_MARGIN")) -> 11.155297 | M9: =IF(A9="","",_xll.BDP(A9&" US Equity","NET_INCOME_MARGIN")) -> #N/A Invalid Field | N9: =IF(A9="","",_xll.BDP(A9&" US Equity","FREE_CASH_FLOW_YIELD")) -> 0.35480726 | O9: =IF(A9="","",_xll.BDP(A9&" US Equity","TOT_DEBT_TO_TOT_EQY")) -> 41.339934 | P9: =IF(A9="","",_xll.BDP(A9&" US Equity","EQY_DVD_YLD_IND")) -> #N/A N/A | Q9: =IF(A9="","",_xll.BDP(A9&" US Equity","BEST_CUR_EV_TO_EBITDA")) -> 10.152692 | R9: =IF(A9="","",_xll.BDP(A9&" US Equity","PX_TO_BOOK_RATIO")) -> 5.2343857 | S9: =IF(A9="","",_xll.BDP(A9&" US Equity","RESEARCH_AND_DEV_TO_REVENUE")) -> #N/A Invalid Field | T9: =IF(A9="","",_xll.BDP(A9&" US Equity","REVENUE_5YR_CAGR")) -> #N/A Invalid Field | U9: =IF(A9="","",0.045+G9*0.05) -> 0.11606631
A10: META | B10: =IF(A10="","",_xll.BDP(A10&" US Equity","NAME")) -> META PLATFORMS INC-CLASS A | C10: =IF(A10="","",_xll.BDP(A10&" US Equity","GICS_SECTOR_NAME")) -> Communication Services | D10: =IF(A10="","",_xll.BDP(A10&" US Equity","GICS_SUB_INDUSTRY_NAME")) -> Interactive Media & Services | E10: =IF(A10="","",_xll.BDP(A10&" US Equity","PX_LAST")) -> 650.47 | F10: =IF(A10="","",_xll.BDP(A10&" US Equity","CUR_MKT_CAP")/1000000000) -> 1645.9212 | G10: =IF(A10="","",_xll.BDP(A10&" US Equity","BETA_RAW_OVERRIDABLE")) -> 1.2868528 | H10: =IF(A10="","",_xll.BDP(A10&" US Equity","BEST_PE_RATIO")) -> 19.2612 | I10: =IF(A10="","",_xll.BDP(A10&" US Equity","RETURN_ON_INV_CAPITAL")) -> 22.027166 | J10: =IF(A10="","",_xll.BDP(A10&" US Equity","RETURN_COM_EQY")) -> 30.238071 | K10: =IF(A10="","",_xll.BDP(A10&" US Equity","GROSS_MARGIN")) -> 81.999443 | L10: =IF(A10="","",_xll.BDP(A10&" US Equity","OPER_MARGIN")) -> 41.437855 | M10: =IF(A10="","",_xll.BDP(A10&" US Equity","NET_INCOME_MARGIN")) -> #N/A Invalid Field | N10: =IF(A10="","",_xll.BDP(A10&" US Equity","FREE_CASH_FLOW_YIELD")) -> 2.8105079 | O10: =IF(A10="","",_xll.BDP(A10&" US Equity","TOT_DEBT_TO_TOT_EQY")) -> 39.163978 | P10: =IF(A10="","",_xll.BDP(A10&" US Equity","EQY_DVD_YLD_IND")) -> 0.32284347 | Q10: =IF(A10="","",_xll.BDP(A10&" US Equity","BEST_CUR_EV_TO_EBITDA")) -> 13.35076 | R10: =IF(A10="","",_xll.BDP(A10&" US Equity","PX_TO_BOOK_RATIO")) -> 7.58432 | S10: =IF(A10="","",_xll.BDP(A10&" US Equity","RESEARCH_AND_DEV_TO_REVENUE")) -> #N/A Invalid Field | T10: =IF(A10="","",_xll.BDP(A10&" US Equity","REVENUE_5YR_CAGR")) -> #N/A Invalid Field | U10: =IF(A10="","",0.045+G10*0.05) -> 0.10934264
A11: V | B11: =IF(A11="","",_xll.BDP(A11&" US Equity","NAME")) -> VISA INC-CLASS A SHARES | C11: =IF(A11="","",_xll.BDP(A11&" US Equity","GICS_SECTOR_NAME")) -> Financials | D11: =IF(A11="","",_xll.BDP(A11&" US Equity","GICS_SUB_INDUSTRY_NAME")) -> Transaction & Payment Processi | E11: =IF(A11="","",_xll.BDP(A11&" US Equity","PX_LAST")) -> 318.855 | F11: =IF(A11="","",_xll.BDP(A11&" US Equity","CUR_MKT_CAP")/1000000000) -> 622.39816 | G11: =IF(A11="","",_xll.BDP(A11&" US Equity","BETA_RAW_OVERRIDABLE")) -> 0.75626543 | H11: =IF(A11="","",_xll.BDP(A11&" US Equity","BEST_PE_RATIO")) -> 24.073613 | I11: =IF(A11="","",_xll.BDP(A11&" US Equity","RETURN_ON_INV_CAPITAL")) -> 34.676108 | J11: =IF(A11="","",_xll.BDP(A11&" US Equity","RETURN_COM_EQY")) -> 54.992198 | K11: =IF(A11="","",_xll.BDP(A11&" US Equity","GROSS_MARGIN")) -> #N/A N/A | L11: =IF(A11="","",_xll.BDP(A11&" US Equity","OPER_MARGIN")) -> 59.985 | M11: =IF(A11="","",_xll.BDP(A11&" US Equity","NET_INCOME_MARGIN")) -> #N/A Invalid Field | N11: =IF(A11="","",_xll.BDP(A11&" US Equity","FREE_CASH_FLOW_YIELD")) -> 3.9170674 | O11: =IF(A11="","",_xll.BDP(A11&" US Equity","TOT_DEBT_TO_TOT_EQY")) -> 68.80688 | P11: =IF(A11="","",_xll.BDP(A11&" US Equity","EQY_DVD_YLD_IND")) -> 0.84050746 | Q11: =IF(A11="","",_xll.BDP(A11&" US Equity","BEST_CUR_EV_TO_EBITDA")) -> 19.368512 | R11: =IF(A11="","",_xll.BDP(A11&" US Equity","PX_TO_BOOK_RATIO")) -> 15.156165 | S11: =IF(A11="","",_xll.BDP(A11&" US Equity","RESEARCH_AND_DEV_TO_REVENUE")) -> #N/A Invalid Field | T11: =IF(A11="","",_xll.BDP(A11&" US Equity","REVENUE_5YR_CAGR")) -> #N/A Invalid Field | U11: =IF(A11="","",0.045+G11*0.05) -> 0.082813272
A12: MA | B12: =IF(A12="","",_xll.BDP(A12&" US Equity","NAME")) -> MASTERCARD INC - A | C12: =IF(A12="","",_xll.BDP(A12&" US Equity","GICS_SECTOR_NAME")) -> Financials | D12: =IF(A12="","",_xll.BDP(A12&" US Equity","GICS_SUB_INDUSTRY_NAME")) -> Transaction & Payment Processi | E12: =IF(A12="","",_xll.BDP(A12&" US Equity","PX_LAST")) -> 525.28 | F12: =IF(A12="","",_xll.BDP(A12&" US Equity","CUR_MKT_CAP")/1000000000) -> 468.52562 | G12: =IF(A12="","",_xll.BDP(A12&" US Equity","BETA_RAW_OVERRIDABLE")) -> 0.78531752 | H12: =IF(A12="","",_xll.BDP(A12&" US Equity","BEST_PE_RATIO")) -> 26.849315 | I12: =IF(A12="","",_xll.BDP(A12&" US Equity","RETURN_ON_INV_CAPITAL")) -> 58.677643 | J12: =IF(A12="","",_xll.BDP(A12&" US Equity","RETURN_COM_EQY")) -> 210.49079 | K12: =IF(A12="","",_xll.BDP(A12&" US Equity","GROSS_MARGIN")) -> #N/A N/A | L12: =IF(A12="","",_xll.BDP(A12&" US Equity","OPER_MARGIN")) -> 57.628618 | M12: =IF(A12="","",_xll.BDP(A12&" US Equity","NET_INCOME_MARGIN")) -> #N/A Invalid Field | N12: =IF(A12="","",_xll.BDP(A12&" US Equity","FREE_CASH_FLOW_YIELD")) -> 3.6145177 | O12: =IF(A12="","",_xll.BDP(A12&" US Equity","TOT_DEBT_TO_TOT_EQY")) -> 256.04183 | P12: =IF(A12="","",_xll.BDP(A12&" US Equity","EQY_DVD_YLD_IND")) -> 0.66250381 | Q12: =IF(A12="","",_xll.BDP(A12&" US Equity","BEST_CUR_EV_TO_EBITDA")) -> 20.444834 | R12: =IF(A12="","",_xll.BDP(A12&" US Equity","PX_TO_BOOK_RATIO")) -> 60.695405 | S12: =IF(A12="","",_xll.BDP(A12&" US Equity","RESEARCH_AND_DEV_TO_REVENUE")) -> #N/A Invalid Field | T12: =IF(A12="","",_xll.BDP(A12&" US Equity","REVENUE_5YR_CAGR")) -> #N/A Invalid Field | U12: =IF(A12="","",0.045+G12*0.05) -> 0.084265876
A13: ACN | B13: =IF(A13="","",_xll.BDP(A13&" US Equity","NAME")) -> ACCENTURE PLC-CL A | C13: =IF(A13="","",_xll.BDP(A13&" US Equity","GICS_SECTOR_NAME")) -> Information Technology | D13: =IF(A13="","",_xll.BDP(A13&" US Equity","GICS_SUB_INDUSTRY_NAME")) -> IT Consulting & Other Services | E13: =IF(A13="","",_xll.BDP(A13&" US Equity","PX_LAST")) -> 223.92 | F13: =IF(A13="","",_xll.BDP(A13&" US Equity","CUR_MKT_CAP")/1000000000) -> 148.0408 | G13: =IF(A13="","",_xll.BDP(A13&" US Equity","BETA_RAW_OVERRIDABLE")) -> 0.60246106 | H13: =IF(A13="","",_xll.BDP(A13&" US Equity","BEST_PE_RATIO")) -> 16.010296 | I13: =IF(A13="","",_xll.BDP(A13&" US Equity","RETURN_ON_INV_CAPITAL")) -> 20.961927 | J13: =IF(A13="","",_xll.BDP(A13&" US Equity","RETURN_COM_EQY")) -> 25.345833 | K13: =IF(A13="","",_xll.BDP(A13&" US Equity","GROSS_MARGIN")) -> 31.913953 | L13: =IF(A13="","",_xll.BDP(A13&" US Equity","OPER_MARGIN")) -> 14.676657 | M13: =IF(A13="","",_xll.BDP(A13&" US Equity","NET_INCOME_MARGIN")) -> #N/A Invalid Field | N13: =IF(A13="","",_xll.BDP(A13&" US Equity","FREE_CASH_FLOW_YIELD")) -> 8.2427933 | O13: =IF(A13="","",_xll.BDP(A13&" US Equity","TOT_DEBT_TO_TOT_EQY")) -> 25.380337 | P13: =IF(A13="","",_xll.BDP(A13&" US Equity","EQY_DVD_YLD_IND")) -> 2.9117542 | Q13: =IF(A13="","",_xll.BDP(A13&" US Equity","BEST_CUR_EV_TO_EBITDA")) -> 10.090769 | R13: =IF(A13="","",_xll.BDP(A13&" US Equity","PX_TO_BOOK_RATIO")) -> 4.4661246 | S13: =IF(A13="","",_xll.BDP(A13&" US Equity","RESEARCH_AND_DEV_TO_REVENUE")) -> #N/A Invalid Field | T13: =IF(A13="","",_xll.BDP(A13&" US Equity","REVENUE_5YR_CAGR")) -> #N/A Invalid Field | U13: =IF(A13="","",0.045+G13*0.05) -> 0.075123053
A14: CRM | B14: =IF(A14="","",_xll.BDP(A14&" US Equity","NAME")) -> SALESFORCE INC | C14: =IF(A14="","",_xll.BDP(A14&" US Equity","GICS_SECTOR_NAME")) -> Information Technology | D14: =IF(A14="","",_xll.BDP(A14&" US Equity","GICS_SUB_INDUSTRY_NAME")) -> Application Software | E14: =IF(A14="","",_xll.BDP(A14&" US Equity","PX_LAST")) -> 190.84 | F14: =IF(A14="","",_xll.BDP(A14&" US Equity","CUR_MKT_CAP")/1000000000) -> 178.81708 | G14: =IF(A14="","",_xll.BDP(A14&" US Equity","BETA_RAW_OVERRIDABLE")) -> 1.334756 | H14: =IF(A14="","",_xll.BDP(A14&" US Equity","BEST_PE_RATIO")) -> 15.093325 | I14: =IF(A14="","",_xll.BDP(A14&" US Equity","RETURN_ON_INV_CAPITAL")) -> 9.4487734 | J14: =IF(A14="","",_xll.BDP(A14&" US Equity","RETURN_COM_EQY")) -> 12.1843 | K14: =IF(A14="","",_xll.BDP(A14&" US Equity","GROSS_MARGIN")) -> 77.192242 | L14: =IF(A14="","",_xll.BDP(A14&" US Equity","OPER_MARGIN")) -> 19.013062 | M14: =IF(A14="","",_xll.BDP(A14&" US Equity","NET_INCOME_MARGIN")) -> #N/A Invalid Field | N14: =IF(A14="","",_xll.BDP(A14&" US Equity","FREE_CASH_FLOW_YIELD")) -> 7.0500016 | O14: =IF(A14="","",_xll.BDP(A14&" US Equity","TOT_DEBT_TO_TOT_EQY")) -> 19.730927 | P14: =IF(A14="","",_xll.BDP(A14&" US Equity","EQY_DVD_YLD_IND")) -> 0.87193462 | Q14: =IF(A14="","",_xll.BDP(A14&" US Equity","BEST_CUR_EV_TO_EBITDA")) -> 9.3342945 | R14: =IF(A14="","",_xll.BDP(A14&" US Equity","PX_TO_BOOK_RATIO")) -> 2.9951396 | S14: =IF(A14="","",_xll.BDP(A14&" US Equity","RESEARCH_AND_DEV_TO_REVENUE")) -> #N/A Invalid Field | T14: =IF(A14="","",_xll.BDP(A14&" US Equity","REVENUE_5YR_CAGR")) -> #N/A Invalid Field | U14: =IF(A14="","",0.045+G14*0.05) -> 0.1117378
A15: ADBE | B15: =IF(A15="","",_xll.BDP(A15&" US Equity","NAME")) -> ADOBE INC | C15: =IF(A15="","",_xll.BDP(A15&" US Equity","GICS_SECTOR_NAME")) -> Information Technology | D15: =IF(A15="","",_xll.BDP(A15&" US Equity","GICS_SUB_INDUSTRY_NAME")) -> Application Software | E15: =IF(A15="","",_xll.BDP(A15&" US Equity","PX_LAST")) -> 264.165 | F15: =IF(A15="","",_xll.BDP(A15&" US Equity","CUR_MKT_CAP")/1000000000) -> 108.43973 | G15: =IF(A15="","",_xll.BDP(A15&" US Equity","BETA_RAW_OVERRIDABLE")) -> 1.0078306 | H15: =IF(A15="","",_xll.BDP(A15&" US Equity","BEST_PE_RATIO")) -> 11.231983 | I15: =IF(A15="","",_xll.BDP(A15&" US Equity","RETURN_ON_INV_CAPITAL")) -> 33.222853 | J15: =IF(A15="","",_xll.BDP(A15&" US Equity","RETURN_COM_EQY")) -> 55.425995 | K15: =IF(A15="","",_xll.BDP(A15&" US Equity","GROSS_MARGIN")) -> 89.267533 | L15: =IF(A15="","",_xll.BDP(A15&" US Equity","OPER_MARGIN")) -> 36.62754 | M15: =IF(A15="","",_xll.BDP(A15&" US Equity","NET_INCOME_MARGIN")) -> #N/A Invalid Field | N15: =IF(A15="","",_xll.BDP(A15&" US Equity","FREE_CASH_FLOW_YIELD")) -> 8.7690573 | O15: =IF(A15="","",_xll.BDP(A15&" US Equity","TOT_DEBT_TO_TOT_EQY")) -> 57.196937 | P15: =IF(A15="","",_xll.BDP(A15&" US Equity","EQY_DVD_YLD_IND")) -> #N/A N/A | Q15: =IF(A15="","",_xll.BDP(A15&" US Equity","BEST_CUR_EV_TO_EBITDA")) -> 8.6890312 | R15: =IF(A15="","",_xll.BDP(A15&" US Equity","PX_TO_BOOK_RATIO")) -> 9.3865739 | S15: =IF(A15="","",_xll.BDP(A15&" US Equity","RESEARCH_AND_DEV_TO_REVENUE")) -> #N/A Invalid Field | T15: =IF(A15="","",_xll.BDP(A15&" US Equity","REVENUE_5YR_CAGR")) -> #N/A Invalid Field | U15: =IF(A15="","",0.045+G15*0.05) -> 0.095391531
A16: NOW | B16: =IF(A16="","",_xll.BDP(A16&" US Equity","NAME")) -> SERVICENOW INC | C16: =IF(A16="","",_xll.BDP(A16&" US Equity","GICS_SECTOR_NAME")) -> Information Technology | D16: =IF(A16="","",_xll.BDP(A16&" US Equity","GICS_SUB_INDUSTRY_NAME")) -> Systems Software | E16: =IF(A16="","",_xll.BDP(A16&" US Equity","PX_LAST")) -> 107 | F16: =IF(A16="","",_xll.BDP(A16&" US Equity","CUR_MKT_CAP")/1000000000) -> 111.9219 | G16: =IF(A16="","",_xll.BDP(A16&" US Equity","BETA_RAW_OVERRIDABLE")) -> 1.4089862 | H16: =IF(A16="","",_xll.BDP(A16&" US Equity","BEST_PE_RATIO")) -> 25.665627 | I16: =IF(A16="","",_xll.BDP(A16&" US Equity","RETURN_ON_INV_CAPITAL")) -> 10.202797 | J16: =IF(A16="","",_xll.BDP(A16&" US Equity","RETURN_COM_EQY")) -> 15.487529 | K16: =IF(A16="","",_xll.BDP(A16&" US Equity","GROSS_MARGIN")) -> 77.534267 | L16: =IF(A16="","",_xll.BDP(A16&" US Equity","OPER_MARGIN")) -> 13.737009 | M16: =IF(A16="","",_xll.BDP(A16&" US Equity","NET_INCOME_MARGIN")) -> #N/A Invalid Field | N16: =IF(A16="","",_xll.BDP(A16&" US Equity","FREE_CASH_FLOW_YIELD")) -> 4.1242633 | O16: =IF(A16="","",_xll.BDP(A16&" US Equity","TOT_DEBT_TO_TOT_EQY")) -> 18.535946 | P16: =IF(A16="","",_xll.BDP(A16&" US Equity","EQY_DVD_YLD_IND")) -> #N/A N/A | Q16: =IF(A16="","",_xll.BDP(A16&" US Equity","BEST_CUR_EV_TO_EBITDA")) -> 17.148487 | R16: =IF(A16="","",_xll.BDP(A16&" US Equity","PX_TO_BOOK_RATIO")) -> 8.6438323 | S16: =IF(A16="","",_xll.BDP(A16&" US Equity","RESEARCH_AND_DEV_TO_REVENUE")) -> #N/A Invalid Field | T16: =IF(A16="","",_xll.BDP(A16&" US Equity","REVENUE_5YR_CAGR")) -> #N/A Invalid Field | U16: =IF(A16="","",0.045+G16*0.05) -> 0.11544931
... A25: GAP | B25: =IF(A25="","",_xll.BDP(A25&" US Equity","NAME")) -> GAP INC/THE | C25: =IF(A25="","",_xll.BDP(A25&" US Equity","GICS_SECTOR_NAME")) -> Consumer Discretionary | D25: =IF(A25="","",_xll.BDP(A25&" US Equity","GICS_SUB_INDUSTRY_NAME")) -> Apparel Retail | E25: =IF(A25="","",_xll.BDP(A25&" US Equity","PX_LAST")) -> 27.675 | F25: =IF(A25="","",_xll.BDP(A25&" US Equity","CUR_MKT_CAP")/1000000000) -> 10.292934 | G25: =IF(A25="","",_xll.BDP(A25&" US Equity","BETA_RAW_OVERRIDABLE")) -> 1.2394717 | H25: =IF(A25="","",_xll.BDP(A25&" US Equity","BEST_PE_RATIO")) -> 12.37148 | I25: =IF(A25="","",_xll.BDP(A25&" US Equity","RETURN_ON_INV_CAPITAL")) -> 9.3427412 | J25: =IF(A25="","",_xll.BDP(A25&" US Equity","RETURN_COM_EQY")) -> 25.095842 | K25: =IF(A25="","",_xll.BDP(A25&" US Equity","GROSS_MARGIN")) -> 41.27668 | L25: =IF(A25="","",_xll.BDP(A25&" US Equity","OPER_MARGIN")) -> 7.3710725 | M25: =IF(A25="","",_xll.BDP(A25&" US Equity","NET_INCOME_MARGIN")) -> #N/A Invalid Field | N25: =IF(A25="","",_xll.BDP(A25&" US Equity","FREE_CASH_FLOW_YIELD")) -> 7.5106375 | O25: =IF(A25="","",_xll.BDP(A25&" US Equity","TOT_DEBT_TO_TOT_EQY")) -> 167.73897 | P25: =IF(A25="","",_xll.BDP(A25&" US Equity","EQY_DVD_YLD_IND")) -> 2.3848239 | Q25: =IF(A25="","",_xll.BDP(A25&" US Equity","BEST_CUR_EV_TO_EBITDA")) -> 5.6313987 | R25: =IF(A25="","",_xll.BDP(A25&" US Equity","PX_TO_BOOK_RATIO")) -> 2.8228955 | S25: =IF(A25="","",_xll.BDP(A25&" US Equity","RESEARCH_AND_DEV_TO_REVENUE")) -> #N/A Invalid Field | T25: =IF(A25="","",_xll.BDP(A25&" US Equity","REVENUE_5YR_CAGR")) -> #N/A Invalid Field | U25: =IF(A25="","",0.045+G25*0.05) -> 0.10697359
B26: =IF(A26="","",_xll.BDP(A26&" US Equity","NAME")) | C26: =IF(A26="","",_xll.BDP(A26&" US Equity","GICS_SECTOR_NAME")) | D26: =IF(A26="","",_xll.BDP(A26&" US Equity","GICS_SUB_INDUSTRY_NAME")) | E26: =IF(A26="","",_xll.BDP(A26&" US Equity","PX_LAST")) | F26: =IF(A26="","",_xll.BDP(A26&" US Equity","CUR_MKT_CAP")/1000000000) | G26: =IF(A26="","",_xll.BDP(A26&" US Equity","BETA_RAW_OVERRIDABLE")) | H26: =IF(A26="","",_xll.BDP(A26&" US Equity","BEST_PE_RATIO")) | I26: =IF(A26="","",_xll.BDP(A26&" US Equity","RETURN_ON_INV_CAPITAL")) | J26: =IF(A26="","",_xll.BDP(A26&" US Equity","RETURN_COM_EQY")) | K26: =IF(A26="","",_xll.BDP(A26&" US Equity","GROSS_MARGIN")) | L26: =IF(A26="","",_xll.BDP(A26&" US Equity","OPER_MARGIN")) | M26: =IF(A26="","",_xll.BDP(A26&" US Equity","NET_INCOME_MARGIN")) | N26: =IF(A26="","",_xll.BDP(A26&" US Equity","FREE_CASH_FLOW_YIELD")) | O26: =IF(A26="","",_xll.BDP(A26&" US Equity","TOT_DEBT_TO_TOT_EQY")) | P26: =IF(A26="","",_xll.BDP(A26&" US Equity","EQY_DVD_YLD_IND")) | Q26: =IF(A26="","",_xll.BDP(A26&" US Equity","BEST_CUR_EV_TO_EBITDA")) | R26: =IF(A26="","",_xll.BDP(A26&" US Equity","PX_TO_BOOK_RATIO")) | S26: =IF(A26="","",_xll.BDP(A26&" US Equity","RESEARCH_AND_DEV_TO_REVENUE")) | T26: =IF(A26="","",_xll.BDP(A26&" US Equity","REVENUE_5YR_CAGR")) | U26: =IF(A26="","",0.045+G26*0.05)
B27: =IF(A27="","",_xll.BDP(A27&" US Equity","NAME")) | C27: =IF(A27="","",_xll.BDP(A27&" US Equity","GICS_SECTOR_NAME")) | D27: =IF(A27="","",_xll.BDP(A27&" US Equity","GICS_SUB_INDUSTRY_NAME")) | E27: =IF(A27="","",_xll.BDP(A27&" US Equity","PX_LAST")) | F27: =IF(A27="","",_xll.BDP(A27&" US Equity","CUR_MKT_CAP")/1000000000) | G27: =IF(A27="","",_xll.BDP(A27&" US Equity","BETA_RAW_OVERRIDABLE")) | H27: =IF(A27="","",_xll.BDP(A27&" US Equity","BEST_PE_RATIO")) | I27: =IF(A27="","",_xll.BDP(A27&" US Equity","RETURN_ON_INV_CAPITAL")) | J27: =IF(A27="","",_xll.BDP(A27&" US Equity","RETURN_COM_EQY")) | K27: =IF(A27="","",_xll.BDP(A27&" US Equity","GROSS_MARGIN")) | L27: =IF(A27="","",_xll.BDP(A27&" US Equity","OPER_MARGIN")) | M27: =IF(A27="","",_xll.BDP(A27&" US Equity","NET_INCOME_MARGIN")) | N27: =IF(A27="","",_xll.BDP(A27&" US Equity","FREE_CASH_FLOW_YIELD")) | O27: =IF(A27="","",_xll.BDP(A27&" US Equity","TOT_DEBT_TO_TOT_EQY")) | P27: =IF(A27="","",_xll.BDP(A27&" US Equity","EQY_DVD_YLD_IND")) | Q27: =IF(A27="","",_xll.BDP(A27&" US Equity","BEST_CUR_EV_TO_EBITDA")) | R27: =IF(A27="","",_xll.BDP(A27&" US Equity","PX_TO_BOOK_RATIO")) | S27: =IF(A27="","",_xll.BDP(A27&" US Equity","RESEARCH_AND_DEV_TO_REVENUE")) | T27: =IF(A27="","",_xll.BDP(A27&" US Equity","REVENUE_5YR_CAGR")) | U27: =IF(A27="","",0.045+G27*0.05)
B28: =IF(A28="","",_xll.BDP(A28&" US Equity","NAME")) | C28: =IF(A28="","",_xll.BDP(A28&" US Equity","GICS_SECTOR_NAME")) | D28: =IF(A28="","",_xll.BDP(A28&" US Equity","GICS_SUB_INDUSTRY_NAME")) | E28: =IF(A28="","",_xll.BDP(A28&" US Equity","PX_LAST")) | F28: =IF(A28="","",_xll.BDP(A28&" US Equity","CUR_MKT_CAP")/1000000000) | G28: =IF(A28="","",_xll.BDP(A28&" US Equity","BETA_RAW_OVERRIDABLE")) | H28: =IF(A28="","",_xll.BDP(A28&" US Equity","BEST_PE_RATIO")) | I28: =IF(A28="","",_xll.BDP(A28&" US Equity","RETURN_ON_INV_CAPITAL")) | J28: =IF(A28="","",_xll.BDP(A28&" US Equity","RETURN_COM_EQY")) | K28: =IF(A28="","",_xll.BDP(A28&" US Equity","GROSS_MARGIN")) | L28: =IF(A28="","",_xll.BDP(A28&" US Equity","OPER_MARGIN")) | M28: =IF(A28="","",_xll.BDP(A28&" US Equity","NET_INCOME_MARGIN")) | N28: =IF(A28="","",_xll.BDP(A28&" US Equity","FREE_CASH_FLOW_YIELD")) | O28: =IF(A28="","",_xll.BDP(A28&" US Equity","TOT_DEBT_TO_TOT_EQY")) | P28: =IF(A28="","",_xll.BDP(A28&" US Equity","EQY_DVD_YLD_IND")) | Q28: =IF(A28="","",_xll.BDP(A28&" US Equity","BEST_CUR_EV_TO_EBITDA")) | R28: =IF(A28="","",_xll.BDP(A28&" US Equity","PX_TO_BOOK_RATIO")) | S28: =IF(A28="","",_xll.BDP(A28&" US Equity","RESEARCH_AND_DEV_TO_REVENUE")) | T28: =IF(A28="","",_xll.BDP(A28&" US Equity","REVENUE_5YR_CAGR")) | U28: =IF(A28="","",0.045+G28*0.05)
B29: =IF(A29="","",_xll.BDP(A29&" US Equity","NAME")) | C29: =IF(A29="","",_xll.BDP(A29&" US Equity","GICS_SECTOR_NAME")) | D29: =IF(A29="","",_xll.BDP(A29&" US Equity","GICS_SUB_INDUSTRY_NAME")) | E29: =IF(A29="","",_xll.BDP(A29&" US Equity","PX_LAST")) | F29: =IF(A29="","",_xll.BDP(A29&" US Equity","CUR_MKT_CAP")/1000000000) | G29: =IF(A29="","",_xll.BDP(A29&" US Equity","BETA_RAW_OVERRIDABLE")) | H29: =IF(A29="","",_xll.BDP(A29&" US Equity","BEST_PE_RATIO")) | I29: =IF(A29="","",_xll.BDP(A29&" US Equity","RETURN_ON_INV_CAPITAL")) | J29: =IF(A29="","",_xll.BDP(A29&" US Equity","RETURN_COM_EQY")) | K29: =IF(A29="","",_xll.BDP(A29&" US Equity","GROSS_MARGIN")) | L29: =IF(A29="","",_xll.BDP(A29&" US Equity","OPER_MARGIN")) | M29: =IF(A29="","",_xll.BDP(A29&" US Equity","NET_INCOME_MARGIN")) | N29: =IF(A29="","",_xll.BDP(A29&" US Equity","FREE_CASH_FLOW_YIELD")) | O29: =IF(A29="","",_xll.BDP(A29&" US Equity","TOT_DEBT_TO_TOT_EQY")) | P29: =IF(A29="","",_xll.BDP(A29&" US Equity","EQY_DVD_YLD_IND")) | Q29: =IF(A29="","",_xll.BDP(A29&" US Equity","BEST_CUR_EV_TO_EBITDA")) | R29: =IF(A29="","",_xll.BDP(A29&" US Equity","PX_TO_BOOK_RATIO")) | S29: =IF(A29="","",_xll.BDP(A29&" US Equity","RESEARCH_AND_DEV_TO_REVENUE")) | T29: =IF(A29="","",_xll.BDP(A29&" US Equity","REVENUE_5YR_CAGR")) | U29: =IF(A29="","",0.045+G29*0.05)
B30: =IF(A30="","",_xll.BDP(A30&" US Equity","NAME")) | C30: =IF(A30="","",_xll.BDP(A30&" US Equity","GICS_SECTOR_NAME")) | D30: =IF(A30="","",_xll.BDP(A30&" US Equity","GICS_SUB_INDUSTRY_NAME")) | E30: =IF(A30="","",_xll.BDP(A30&" US Equity","PX_LAST")) | F30: =IF(A30="","",_xll.BDP(A30&" US Equity","CUR_MKT_CAP")/1000000000) | G30: =IF(A30="","",_xll.BDP(A30&" US Equity","BETA_RAW_OVERRIDABLE")) | H30: =IF(A30="","",_xll.BDP(A30&" US Equity","BEST_PE_RATIO")) | I30: =IF(A30="","",_xll.BDP(A30&" US Equity","RETURN_ON_INV_CAPITAL")) | J30: =IF(A30="","",_xll.BDP(A30&" US Equity","RETURN_COM_EQY")) | K30: =IF(A30="","",_xll.BDP(A30&" US Equity","GROSS_MARGIN")) | L30: =IF(A30="","",_xll.BDP(A30&" US Equity","OPER_MARGIN")) | M30: =IF(A30="","",_xll.BDP(A30&" US Equity","NET_INCOME_MARGIN")) | N30: =IF(A30="","",_xll.BDP(A30&" US Equity","FREE_CASH_FLOW_YIELD")) | O30: =IF(A30="","",_xll.BDP(A30&" US Equity","TOT_DEBT_TO_TOT_EQY")) | P30: =IF(A30="","",_xll.BDP(A30&" US Equity","EQY_DVD_YLD_IND")) | Q30: =IF(A30="","",_xll.BDP(A30&" US Equity","BEST_CUR_EV_TO_EBITDA")) | R30: =IF(A30="","",_xll.BDP(A30&" US Equity","PX_TO_BOOK_RATIO")) | S30: =IF(A30="","",_xll.BDP(A30&" US Equity","RESEARCH_AND_DEV_TO_REVENUE")) | T30: =IF(A30="","",_xll.BDP(A30&" US Equity","REVENUE_5YR_CAGR")) | U30: =IF(A30="","",0.045+G30*0.05)
B31: =IF(A31="","",_xll.BDP(A31&" US Equity","NAME")) | C31: =IF(A31="","",_xll.BDP(A31&" US Equity","GICS_SECTOR_NAME")) | D31: =IF(A31="","",_xll.BDP(A31&" US Equity","GICS_SUB_INDUSTRY_NAME")) | E31: =IF(A31="","",_xll.BDP(A31&" US Equity","PX_LAST")) | F31: =IF(A31="","",_xll.BDP(A31&" US Equity","CUR_MKT_CAP")/1000000000) | G31: =IF(A31="","",_xll.BDP(A31&" US Equity","BETA_RAW_OVERRIDABLE")) | H31: =IF(A31="","",_xll.BDP(A31&" US Equity","BEST_PE_RATIO")) | I31: =IF(A31="","",_xll.BDP(A31&" US Equity","RETURN_ON_INV_CAPITAL")) | J31: =IF(A31="","",_xll.BDP(A31&" US Equity","RETURN_COM_EQY")) | K31: =IF(A31="","",_xll.BDP(A31&" US Equity","GROSS_MARGIN")) | L31: =IF(A31="","",_xll.BDP(A31&" US Equity","OPER_MARGIN")) | M31: =IF(A31="","",_xll.BDP(A31&" US Equity","NET_INCOME_MARGIN")) | N31: =IF(A31="","",_xll.BDP(A31&" US Equity","FREE_CASH_FLOW_YIELD")) | O31: =IF(A31="","",_xll.BDP(A31&" US Equity","TOT_DEBT_TO_TOT_EQY")) | P31: =IF(A31="","",_xll.BDP(A31&" US Equity","EQY_DVD_YLD_IND")) | Q31: =IF(A31="","",_xll.BDP(A31&" US Equity","BEST_CUR_EV_TO_EBITDA")) | R31: =IF(A31="","",_xll.BDP(A31&" US Equity","PX_TO_BOOK_RATIO")) | S31: =IF(A31="","",_xll.BDP(A31&" US Equity","RESEARCH_AND_DEV_TO_REVENUE")) | T31: =IF(A31="","",_xll.BDP(A31&" US Equity","REVENUE_5YR_CAGR")) | U31: =IF(A31="","",0.045+G31*0.05)
B32: =IF(A32="","",_xll.BDP(A32&" US Equity","NAME")) | C32: =IF(A32="","",_xll.BDP(A32&" US Equity","GICS_SECTOR_NAME")) | D32: =IF(A32="","",_xll.BDP(A32&" US Equity","GICS_SUB_INDUSTRY_NAME")) | E32: =IF(A32="","",_xll.BDP(A32&" US Equity","PX_LAST")) | F32: =IF(A32="","",_xll.BDP(A32&" US Equity","CUR_MKT_CAP")/1000000000) | G32: =IF(A32="","",_xll.BDP(A32&" US Equity","BETA_RAW_OVERRIDABLE")) | H32: =IF(A32="","",_xll.BDP(A32&" US Equity","BEST_PE_RATIO")) | I32: =IF(A32="","",_xll.BDP(A32&" US Equity","RETURN_ON_INV_CAPITAL")) | J32: =IF(A32="","",_xll.BDP(A32&" US Equity","RETURN_COM_EQY")) | K32: =IF(A32="","",_xll.BDP(A32&" US Equity","GROSS_MARGIN")) | L32: =IF(A32="","",_xll.BDP(A32&" US Equity","OPER_MARGIN")) | M32: =IF(A32="","",_xll.BDP(A32&" US Equity","NET_INCOME_MARGIN")) | N32: =IF(A32="","",_xll.BDP(A32&" US Equity","FREE_CASH_FLOW_YIELD")) | O32: =IF(A32="","",_xll.BDP(A32&" US Equity","TOT_DEBT_TO_TOT_EQY")) | P32: =IF(A32="","",_xll.BDP(A32&" US Equity","EQY_DVD_YLD_IND")) | Q32: =IF(A32="","",_xll.BDP(A32&" US Equity","BEST_CUR_EV_TO_EBITDA")) | R32: =IF(A32="","",_xll.BDP(A32&" US Equity","PX_TO_BOOK_RATIO")) | S32: =IF(A32="","",_xll.BDP(A32&" US Equity","RESEARCH_AND_DEV_TO_REVENUE")) | T32: =IF(A32="","",_xll.BDP(A32&" US Equity","REVENUE_5YR_CAGR")) | U32: =IF(A32="","",0.045+G32*0.05)
B33: =IF(A33="","",_xll.BDP(A33&" US Equity","NAME")) | C33: =IF(A33="","",_xll.BDP(A33&" US Equity","GICS_SECTOR_NAME")) | D33: =IF(A33="","",_xll.BDP(A33&" US Equity","GICS_SUB_INDUSTRY_NAME")) | E33: =IF(A33="","",_xll.BDP(A33&" US Equity","PX_LAST")) | F33: =IF(A33="","",_xll.BDP(A33&" US Equity","CUR_MKT_CAP")/1000000000) | G33: =IF(A33="","",_xll.BDP(A33&" US Equity","BETA_RAW_OVERRIDABLE")) | H33: =IF(A33="","",_xll.BDP(A33&" US Equity","BEST_PE_RATIO")) | I33: =IF(A33="","",_xll.BDP(A33&" US Equity","RETURN_ON_INV_CAPITAL")) | J33: =IF(A33="","",_xll.BDP(A33&" US Equity","RETURN_COM_EQY")) | K33: =IF(A33="","",_xll.BDP(A33&" US Equity","GROSS_MARGIN")) | L33: =IF(A33="","",_xll.BDP(A33&" US Equity","OPER_MARGIN")) | M33: =IF(A33="","",_xll.BDP(A33&" US Equity","NET_INCOME_MARGIN")) | N33: =IF(A33="","",_xll.BDP(A33&" US Equity","FREE_CASH_FLOW_YIELD")) | O33: =IF(A33="","",_xll.BDP(A33&" US Equity","TOT_DEBT_TO_TOT_EQY")) | P33: =IF(A33="","",_xll.BDP(A33&" US Equity","EQY_DVD_YLD_IND")) | Q33: =IF(A33="","",_xll.BDP(A33&" US Equity","BEST_CUR_EV_TO_EBITDA")) | R33: =IF(A33="","",_xll.BDP(A33&" US Equity","PX_TO_BOOK_RATIO")) | S33: =IF(A33="","",_xll.BDP(A33&" US Equity","RESEARCH_AND_DEV_TO_REVENUE")) | T33: =IF(A33="","",_xll.BDP(A33&" US Equity","REVENUE_5YR_CAGR")) | U33: =IF(A33="","",0.045+G33*0.05)
B34: =IF(A34="","",_xll.BDP(A34&" US Equity","NAME")) | C34: =IF(A34="","",_xll.BDP(A34&" US Equity","GICS_SECTOR_NAME")) | D34: =IF(A34="","",_xll.BDP(A34&" US Equity","GICS_SUB_INDUSTRY_NAME")) | E34: =IF(A34="","",_xll.BDP(A34&" US Equity","PX_LAST")) | F34: =IF(A34="","",_xll.BDP(A34&" US Equity","CUR_MKT_CAP")/1000000000) | G34: =IF(A34="","",_xll.BDP(A34&" US Equity","BETA_RAW_OVERRIDABLE")) | H34: =IF(A34="","",_xll.BDP(A34&" US Equity","BEST_PE_RATIO")) | I34: =IF(A34="","",_xll.BDP(A34&" US Equity","RETURN_ON_INV_CAPITAL")) | J34: =IF(A34="","",_xll.BDP(A34&" US Equity","RETURN_COM_EQY")) | K34: =IF(A34="","",_xll.BDP(A34&" US Equity","GROSS_MARGIN")) | L34: =IF(A34="","",_xll.BDP(A34&" US Equity","OPER_MARGIN")) | M34: =IF(A34="","",_xll.BDP(A34&" US Equity","NET_INCOME_MARGIN")) | N34: =IF(A34="","",_xll.BDP(A34&" US Equity","FREE_CASH_FLOW_YIELD")) | O34: =IF(A34="","",_xll.BDP(A34&" US Equity","TOT_DEBT_TO_TOT_EQY")) | P34: =IF(A34="","",_xll.BDP(A34&" US Equity","EQY_DVD_YLD_IND")) | Q34: =IF(A34="","",_xll.BDP(A34&" US Equity","BEST_CUR_EV_TO_EBITDA")) | R34: =IF(A34="","",_xll.BDP(A34&" US Equity","PX_TO_BOOK_RATIO")) | S34: =IF(A34="","",_xll.BDP(A34&" US Equity","RESEARCH_AND_DEV_TO_REVENUE")) | T34: =IF(A34="","",_xll.BDP(A34&" US Equity","REVENUE_5YR_CAGR")) | U34: =IF(A34="","",0.045+G34*0.05)
B35: =IF(A35="","",_xll.BDP(A35&" US Equity","NAME")) | C35: =IF(A35="","",_xll.BDP(A35&" US Equity","GICS_SECTOR_NAME")) | D35: =IF(A35="","",_xll.BDP(A35&" US Equity","GICS_SUB_INDUSTRY_NAME")) | E35: =IF(A35="","",_xll.BDP(A35&" US Equity","PX_LAST")) | F35: =IF(A35="","",_xll.BDP(A35&" US Equity","CUR_MKT_CAP")/1000000000) | G35: =IF(A35="","",_xll.BDP(A35&" US Equity","BETA_RAW_OVERRIDABLE")) | H35: =IF(A35="","",_xll.BDP(A35&" US Equity","BEST_PE_RATIO")) | I35: =IF(A35="","",_xll.BDP(A35&" US Equity","RETURN_ON_INV_CAPITAL")) | J35: =IF(A35="","",_xll.BDP(A35&" US Equity","RETURN_COM_EQY")) | K35: =IF(A35="","",_xll.BDP(A35&" US Equity","GROSS_MARGIN")) | L35: =IF(A35="","",_xll.BDP(A35&" US Equity","OPER_MARGIN")) | M35: =IF(A35="","",_xll.BDP(A35&" US Equity","NET_INCOME_MARGIN")) | N35: =IF(A35="","",_xll.BDP(A35&" US Equity","FREE_CASH_FLOW_YIELD")) | O35: =IF(A35="","",_xll.BDP(A35&" US Equity","TOT_DEBT_TO_TOT_EQY")) | P35: =IF(A35="","",_xll.BDP(A35&" US Equity","EQY_DVD_YLD_IND")) | Q35: =IF(A35="","",_xll.BDP(A35&" US Equity","BEST_CUR_EV_TO_EBITDA")) | R35: =IF(A35="","",_xll.BDP(A35&" US Equity","PX_TO_BOOK_RATIO")) | S35: =IF(A35="","",_xll.BDP(A35&" US Equity","RESEARCH_AND_DEV_TO_REVENUE")) | T35: =IF(A35="","",_xll.BDP(A35&" US Equity","REVENUE_5YR_CAGR")) | U35: =IF(A35="","",0.045+G35*0.05)
B36: =IF(A36="","",_xll.BDP(A36&" US Equity","NAME")) | C36: =IF(A36="","",_xll.BDP(A36&" US Equity","GICS_SECTOR_NAME")) | D36: =IF(A36="","",_xll.BDP(A36&" US Equity","GICS_SUB_INDUSTRY_NAME")) | E36: =IF(A36="","",_xll.BDP(A36&" US Equity","PX_LAST")) | F36: =IF(A36="","",_xll.BDP(A36&" US Equity","CUR_MKT_CAP")/1000000000) | G36: =IF(A36="","",_xll.BDP(A36&" US Equity","BETA_RAW_OVERRIDABLE")) | H36: =IF(A36="","",_xll.BDP(A36&" US Equity","BEST_PE_RATIO")) | I36: =IF(A36="","",_xll.BDP(A36&" US Equity","RETURN_ON_INV_CAPITAL")) | J36: =IF(A36="","",_xll.BDP(A36&" US Equity","RETURN_COM_EQY")) | K36: =IF(A36="","",_xll.BDP(A36&" US Equity","GROSS_MARGIN")) | L36: =IF(A36="","",_xll.BDP(A36&" US Equity","OPER_MARGIN")) | M36: =IF(A36="","",_xll.BDP(A36&" US Equity","NET_INCOME_MARGIN")) | N36: =IF(A36="","",_xll.BDP(A36&" US Equity","FREE_CASH_FLOW_YIELD")) | O36: =IF(A36="","",_xll.BDP(A36&" US Equity","TOT_DEBT_TO_TOT_EQY")) | P36: =IF(A36="","",_xll.BDP(A36&" US Equity","EQY_DVD_YLD_IND")) | Q36: =IF(A36="","",_xll.BDP(A36&" US Equity","BEST_CUR_EV_TO_EBITDA")) | R36: =IF(A36="","",_xll.BDP(A36&" US Equity","PX_TO_BOOK_RATIO")) | S36: =IF(A36="","",_xll.BDP(A36&" US Equity","RESEARCH_AND_DEV_TO_REVENUE")) | T36: =IF(A36="","",_xll.BDP(A36&" US Equity","REVENUE_5YR_CAGR")) | U36: =IF(A36="","",0.045+G36*0.05)
B37: =IF(A37="","",_xll.BDP(A37&" US Equity","NAME")) | C37: =IF(A37="","",_xll.BDP(A37&" US Equity","GICS_SECTOR_NAME")) | D37: =IF(A37="","",_xll.BDP(A37&" US Equity","GICS_SUB_INDUSTRY_NAME")) | E37: =IF(A37="","",_xll.BDP(A37&" US Equity","PX_LAST")) | F37: =IF(A37="","",_xll.BDP(A37&" US Equity","CUR_MKT_CAP")/1000000000) | G37: =IF(A37="","",_xll.BDP(A37&" US Equity","BETA_RAW_OVERRIDABLE")) | H37: =IF(A37="","",_xll.BDP(A37&" US Equity","BEST_PE_RATIO")) | I37: =IF(A37="","",_xll.BDP(A37&" US Equity","RETURN_ON_INV_CAPITAL")) | J37: =IF(A37="","",_xll.BDP(A37&" US Equity","RETURN_COM_EQY")) | K37: =IF(A37="","",_xll.BDP(A37&" US Equity","GROSS_MARGIN")) | L37: =IF(A37="","",_xll.BDP(A37&" US Equity","OPER_MARGIN")) | M37: =IF(A37="","",_xll.BDP(A37&" US Equity","NET_INCOME_MARGIN")) | N37: =IF(A37="","",_xll.BDP(A37&" US Equity","FREE_CASH_FLOW_YIELD")) | O37: =IF(A37="","",_xll.BDP(A37&" US Equity","TOT_DEBT_TO_TOT_EQY")) | P37: =IF(A37="","",_xll.BDP(A37&" US Equity","EQY_DVD_YLD_IND")) | Q37: =IF(A37="","",_xll.BDP(A37&" US Equity","BEST_CUR_EV_TO_EBITDA")) | R37: =IF(A37="","",_xll.BDP(A37&" US Equity","PX_TO_BOOK_RATIO")) | S37: =IF(A37="","",_xll.BDP(A37&" US Equity","RESEARCH_AND_DEV_TO_REVENUE")) | T37: =IF(A37="","",_xll.BDP(A37&" US Equity","REVENUE_5YR_CAGR")) | U37: =IF(A37="","",0.045+G37*0.05)
... B54: =IF(A54="","",_xll.BDP(A54&" US Equity","NAME")) | C54: =IF(A54="","",_xll.BDP(A54&" US Equity","GICS_SECTOR_NAME")) | D54: =IF(A54="","",_xll.BDP(A54&" US Equity","GICS_SUB_INDUSTRY_NAME")) | E54: =IF(A54="","",_xll.BDP(A54&" US Equity","PX_LAST")) | F54: =IF(A54="","",_xll.BDP(A54&" US Equity","CUR_MKT_CAP")/1000000000) | G54: =IF(A54="","",_xll.BDP(A54&" US Equity","BETA_RAW_OVERRIDABLE")) | H54: =IF(A54="","",_xll.BDP(A54&" US Equity","BEST_PE_RATIO")) | I54: =IF(A54="","",_xll.BDP(A54&" US Equity","RETURN_ON_INV_CAPITAL")) | J54: =IF(A54="","",_xll.BDP(A54&" US Equity","RETURN_COM_EQY")) | K54: =IF(A54="","",_xll.BDP(A54&" US Equity","GROSS_MARGIN")) | L54: =IF(A54="","",_xll.BDP(A54&" US Equity","OPER_MARGIN")) | M54: =IF(A54="","",_xll.BDP(A54&" US Equity","NET_INCOME_MARGIN")) | N54: =IF(A54="","",_xll.BDP(A54&" US Equity","FREE_CASH_FLOW_YIELD")) | O54: =IF(A54="","",_xll.BDP(A54&" US Equity","TOT_DEBT_TO_TOT_EQY")) | P54: =IF(A54="","",_xll.BDP(A54&" US Equity","EQY_DVD_YLD_IND")) | Q54: =IF(A54="","",_xll.BDP(A54&" US Equity","BEST_CUR_EV_TO_EBITDA")) | R54: =IF(A54="","",_xll.BDP(A54&" US Equity","PX_TO_BOOK_RATIO")) | S54: =IF(A54="","",_xll.BDP(A54&" US Equity","RESEARCH_AND_DEV_TO_REVENUE")) | T54: =IF(A54="","",_xll.BDP(A54&" US Equity","REVENUE_5YR_CAGR")) | U54: =IF(A54="","",0.045+G54*0.05)

Sheet Moat Scoring
A1: Moat & AI Risk Scoring
A2: Scores AUTO-POPULATE from sector defaults via VLOOKUP. Type over any cell to override with your own assessment. Blue cells = sector defaults; type to override.
A3: NOTE: When you add a ticker in Portfolio Input and Bloomberg fills the GICS Sector, these scores auto-fill. Override by simply typing a new value.
A4: Ticker | B4: SC (25%) | C4: NE (20%) | D4: IA (25%) | E4: CA (15%) | F4: ES (15%) | G4: Moat | H4: LS (25%) | I4: VCD (25%) | J4: DME (15%) | K4: ANC (20%) | L4: CIR (15%) | M4: AI Risk | N4: Net Moat | O4: Tier | P4: Base CAP | Q4: Adj CAP | R4: WACC+ (bp) | S4: Base P/E | T4: Adj P/E | U4: Haircut (%)
A5: ='Portfolio Input'!A5 -> AAPL | B5: =IF('Portfolio Input'!C5="","",IFERROR(VLOOKUP('Portfolio Input'!C5,'Sector Analysis'!$A$4:$O$15,2,FALSE()),"")) -> 4 | C5: =IF('Portfolio Input'!C5="","",IFERROR(VLOOKUP('Portfolio Input'!C5,'Sector Analysis'!$A$4:$O$15,3,FALSE()),"")) -> 4 | D5: =IF('Portfolio Input'!C5="","",IFERROR(VLOOKUP('Portfolio Input'!C5,'Sector Analysis'!$A$4:$O$15,4,FALSE()),"")) -> 4 | E5: =IF('Portfolio Input'!C5="","",IFERROR(VLOOKUP('Portfolio Input'!C5,'Sector Analysis'!$A$4:$O$15,5,FALSE()),"")) -> 3 | F5: =IF('Portfolio Input'!C5="","",IFERROR(VLOOKUP('Portfolio Input'!C5,'Sector Analysis'!$A$4:$O$15,6,FALSE()),"")) -> 2 | G5: =IF(A5="","",B5*0.25+C5*0.2+D5*0.25+E5*0.15+F5*0.15) -> 3.55 | H5: =IF('Portfolio Input'!C5="","",IFERROR(VLOOKUP('Portfolio Input'!C5,'Sector Analysis'!$A$4:$O$15,8,FALSE()),"")) -> 3 | I5: =IF('Portfolio Input'!C5="","",IFERROR(VLOOKUP('Portfolio Input'!C5,'Sector Analysis'!$A$4:$O$15,9,FALSE()),"")) -> 2 | J5: =IF('Portfolio Input'!C5="","",IFERROR(VLOOKUP('Portfolio Input'!C5,'Sector Analysis'!$A$4:$O$15,10,FALSE()),"")) -> 3 | K5: =IF('Portfolio Input'!C5="","",IFERROR(VLOOKUP('Portfolio Input'!C5,'Sector Analysis'!$A$4:$O$15,11,FALSE()),"")) -> 4 | L5: =IF('Portfolio Input'!C5="","",IFERROR(VLOOKUP('Portfolio Input'!C5,'Sector Analysis'!$A$4:$O$15,12,FALSE()),"")) -> 3 | M5: =IF(A5="","",H5*0.25+I5*0.25+J5*0.15+K5*0.2+L5*0.15) -> 2.95 | N5: =IF(A5="","",G5-M5) -> 0.6 | O5: =IF(A5="","",IF(N5<=-2,"CRITICAL",IF(N5<=-0.5,"HIGH",IF(N5<=0.5,"MEDIUM",IF(N5<=1.5,"LOW-MEDIUM","LOW"))))) -> LOW-MEDIUM | P5: =IF(A5="","",IF(G5>=4,22,IF(G5>=3.5,18,IF(G5>=3,14,IF(G5>=2.5,10,IF(G5>=2,7,4)))))) -> 18 | Q5: =IF(A5="","",MAX(2,ROUND(P5*(1-MAX(0,(M5-1.5)*0.15)),0))) -> 14 | R5: =IF(A5="","",MIN(400,IF(M5>=4,300,IF(M5>=3.5,225,IF(M5>=3,150,IF(M5>=2.5,100,IF(M5>=2,50,0))))))) -> 100 | S5: =IF(A5="","",IF('Portfolio Input'!U5<=0.02,30,MIN(50,MAX(5,(1/('Portfolio Input'!U5-0.02))*(1-((1.02)/(1+'Portfolio Input'!U5))^P5)+((1.02)/(1+'Portfolio Input'!U5))^P5*(1/('Portfolio Input'!U5-0.02)))))) -> 12.422963 | T5: =IF(A5="","",IF(('Portfolio Input'!U5+R5/10000)<=0.02,30,MIN(50,MAX(5,(1/(('Portfolio Input'!U5+R5/10000)-0.02))*(1-((1.02)/(1+('Portfolio Input'!U5+R5/10000)))^Q5)+((1.02)/(1+('Portfolio Input'!U5+R5/10000)))^Q5*(1/(('Portfolio Input'!U5+R5/10000)-0.02)))))) -> 11.0502 | U5: =IF(A5="","",IF(S5>0,(S5-T5)/S5*100,0)) -> 11.0502
A6: ='Portfolio Input'!A6 -> MSFT | B6: =IF('Portfolio Input'!C6="","",IFERROR(VLOOKUP('Portfolio Input'!C6,'Sector Analysis'!$A$4:$O$15,2,FALSE()),"")) -> 4 | C6: =IF('Portfolio Input'!C6="","",IFERROR(VLOOKUP('Portfolio Input'!C6,'Sector Analysis'!$A$4:$O$15,3,FALSE()),"")) -> 4 | D6: =IF('Portfolio Input'!C6="","",IFERROR(VLOOKUP('Portfolio Input'!C6,'Sector Analysis'!$A$4:$O$15,4,FALSE()),"")) -> 4 | E6: =IF('Portfolio Input'!C6="","",IFERROR(VLOOKUP('Portfolio Input'!C6,'Sector Analysis'!$A$4:$O$15,5,FALSE()),"")) -> 3 | F6: =IF('Portfolio Input'!C6="","",IFERROR(VLOOKUP('Portfolio Input'!C6,'Sector Analysis'!$A$4:$O$15,6,FALSE()),"")) -> 2 | G6: =IF(A6="","",B6*0.25+C6*0.2+D6*0.25+E6*0.15+F6*0.15) -> 3.55 | H6: =IF('Portfolio Input'!C6="","",IFERROR(VLOOKUP('Portfolio Input'!C6,'Sector Analysis'!$A$4:$O$15,8,FALSE()),"")) -> 3 | I6: =IF('Portfolio Input'!C6="","",IFERROR(VLOOKUP('Portfolio Input'!C6,'Sector Analysis'!$A$4:$O$15,9,FALSE()),"")) -> 2 | J6: =IF('Portfolio Input'!C6="","",IFERROR(VLOOKUP('Portfolio Input'!C6,'Sector Analysis'!$A$4:$O$15,10,FALSE()),"")) -> 3 | K6: =IF('Portfolio Input'!C6="","",IFERROR(VLOOKUP('Portfolio Input'!C6,'Sector Analysis'!$A$4:$O$15,11,FALSE()),"")) -> 4 | L6: =IF('Portfolio Input'!C6="","",IFERROR(VLOOKUP('Portfolio Input'!C6,'Sector Analysis'!$A$4:$O$15,12,FALSE()),"")) -> 3 | M6: =IF(A6="","",H6*0.25+I6*0.25+J6*0.15+K6*0.2+L6*0.15) -> 2.95 | N6: =IF(A6="","",G6-M6) -> 0.6 | O6: =IF(A6="","",IF(N6<=-2,"CRITICAL",IF(N6<=-0.5,"HIGH",IF(N6<=0.5,"MEDIUM",IF(N6<=1.5,"LOW-MEDIUM","LOW"))))) -> LOW-MEDIUM | P6: =IF(A6="","",IF(G6>=4,22,IF(G6>=3.5,18,IF(G6>=3,14,IF(G6>=2.5,10,IF(G6>=2,7,4)))))) -> 18 | Q6: =IF(A6="","",MAX(2,ROUND(P6*(1-MAX(0,(M6-1.5)*0.15)),0))) -> 14 | R6: =IF(A6="","",MIN(400,IF(M6>=4,300,IF(M6>=3.5,225,IF(M6>=3,150,IF(M6>=2.5,100,IF(M6>=2,50,0))))))) -> 100 | S6: =IF(A6="","",IF('Portfolio Input'!U6<=0.02,30,MIN(50,MAX(5,(1/('Portfolio Input'!U6-0.02))*(1-((1.02)/(1+'Portfolio Input'!U6))^P6)+((1.02)/(1+'Portfolio Input'!U6))^P6*(1/('Portfolio Input'!U6-0.02)))))) -> 13.128651 | T6: =IF(A6="","",IF(('Portfolio Input'!U6+R6/10000)<=0.02,30,MIN(50,MAX(5,(1/(('Portfolio Input'!U6+R6/10000)-0.02))*(1-((1.02)/(1+('Portfolio Input'!U6+R6/10000)))^Q6)+((1.02)/(1+('Portfolio Input'!U6+R6/10000)))^Q6*(1/(('Portfolio Input'!U6+R6/10000)-0.02)))))) -> 11.605063 | U6: =IF(A6="","",IF(S6>0,(S6-T6)/S6*100,0)) -> 11.605063
A7: ='Portfolio Input'!A7 -> GOOGL | B7: =IF('Portfolio Input'!C7="","",IFERROR(VLOOKUP('Portfolio Input'!C7,'Sector Analysis'!$A$4:$O$15,2,FALSE()),"")) -> 3 | C7: =IF('Portfolio Input'!C7="","",IFERROR(VLOOKUP('Portfolio Input'!C7,'Sector Analysis'!$A$4:$O$15,3,FALSE()),"")) -> 5 | D7: =IF('Portfolio Input'!C7="","",IFERROR(VLOOKUP('Portfolio Input'!C7,'Sector Analysis'!$A$4:$O$15,4,FALSE()),"")) -> 4 | E7: =IF('Portfolio Input'!C7="","",IFERROR(VLOOKUP('Portfolio Input'!C7,'Sector Analysis'!$A$4:$O$15,5,FALSE()),"")) -> 2 | F7: =IF('Portfolio Input'!C7="","",IFERROR(VLOOKUP('Portfolio Input'!C7,'Sector Analysis'!$A$4:$O$15,6,FALSE()),"")) -> 3 | G7: =IF(A7="","",B7*0.25+C7*0.2+D7*0.25+E7*0.15+F7*0.15) -> 3.5 | H7: =IF('Portfolio Input'!C7="","",IFERROR(VLOOKUP('Portfolio Input'!C7,'Sector Analysis'!$A$4:$O$15,8,FALSE()),"")) -> 3 | I7: =IF('Portfolio Input'!C7="","",IFERROR(VLOOKUP('Portfolio Input'!C7,'Sector Analysis'!$A$4:$O$15,9,FALSE()),"")) -> 3 | J7: =IF('Portfolio Input'!C7="","",IFERROR(VLOOKUP('Portfolio Input'!C7,'Sector Analysis'!$A$4:$O$15,10,FALSE()),"")) -> 4 | K7: =IF('Portfolio Input'!C7="","",IFERROR(VLOOKUP('Portfolio Input'!C7,'Sector Analysis'!$A$4:$O$15,11,FALSE()),"")) -> 3 | L7: =IF('Portfolio Input'!C7="","",IFERROR(VLOOKUP('Portfolio Input'!C7,'Sector Analysis'!$A$4:$O$15,12,FALSE()),"")) -> 4 | M7: =IF(A7="","",H7*0.25+I7*0.25+J7*0.15+K7*0.2+L7*0.15) -> 3.3 | N7: =IF(A7="","",G7-M7) -> 0.2 | O7: =IF(A7="","",IF(N7<=-2,"CRITICAL",IF(N7<=-0.5,"HIGH",IF(N7<=0.5,"MEDIUM",IF(N7<=1.5,"LOW-MEDIUM","LOW"))))) -> MEDIUM | P7: =IF(A7="","",IF(G7>=4,22,IF(G7>=3.5,18,IF(G7>=3,14,IF(G7>=2.5,10,IF(G7>=2,7,4)))))) -> 18 | Q7: =IF(A7="","",MAX(2,ROUND(P7*(1-MAX(0,(M7-1.5)*0.15)),0))) -> 13 | R7: =IF(A7="","",MIN(400,IF(M7>=4,300,IF(M7>=3.5,225,IF(M7>=3,150,IF(M7>=2.5,100,IF(M7>=2,50,0))))))) -> 150 | S7: =IF(A7="","",IF('Portfolio Input'!U7<=0.02,30,MIN(50,MAX(5,(1/('Portfolio Input'!U7-0.02))*(1-((1.02)/(1+'Portfolio Input'!U7))^P7)+((1.02)/(1+'Portfolio Input'!U7))^P7*(1/('Portfolio Input'!U7-0.02)))))) -> 12.777079 | T7: =IF(A7="","",IF(('Portfolio Input'!U7+R7/10000)<=0.02,30,MIN(50,MAX(5,(1/(('Portfolio Input'!U7+R7/10000)-0.02))*(1-((1.02)/(1+('Portfolio Input'!U7+R7/10000)))^Q7)+((1.02)/(1+('Portfolio Input'!U7+R7/10000)))^Q7*(1/(('Portfolio Input'!U7+R7/10000)-0.02)))))) -> 10.722118 | U7: =IF(A7="","",IF(S7>0,(S7-T7)/S7*100,0)) -> 16.083178
A8: ='Portfolio Input'!A8 -> NVDA | B8: =IF('Portfolio Input'!C8="","",IFERROR(VLOOKUP('Portfolio Input'!C8,'Sector Analysis'!$A$4:$O$15,2,FALSE()),"")) -> 4 | C8: =IF('Portfolio Input'!C8="","",IFERROR(VLOOKUP('Portfolio Input'!C8,'Sector Analysis'!$A$4:$O$15,3,FALSE()),"")) -> 4 | D8: =IF('Portfolio Input'!C8="","",IFERROR(VLOOKUP('Portfolio Input'!C8,'Sector Analysis'!$A$4:$O$15,4,FALSE()),"")) -> 4 | E8: =IF('Portfolio Input'!C8="","",IFERROR(VLOOKUP('Portfolio Input'!C8,'Sector Analysis'!$A$4:$O$15,5,FALSE()),"")) -> 3 | F8: =IF('Portfolio Input'!C8="","",IFERROR(VLOOKUP('Portfolio Input'!C8,'Sector Analysis'!$A$4:$O$15,6,FALSE()),"")) -> 2 | G8: =IF(A8="","",B8*0.25+C8*0.2+D8*0.25+E8*0.15+F8*0.15) -> 3.55 | H8: =IF('Portfolio Input'!C8="","",IFERROR(VLOOKUP('Portfolio Input'!C8,'Sector Analysis'!$A$4:$O$15,8,FALSE()),"")) -> 3 | I8: =IF('Portfolio Input'!C8="","",IFERROR(VLOOKUP('Portfolio Input'!C8,'Sector Analysis'!$A$4:$O$15,9,FALSE()),"")) -> 2 | J8: =IF('Portfolio Input'!C8="","",IFERROR(VLOOKUP('Portfolio Input'!C8,'Sector Analysis'!$A$4:$O$15,10,FALSE()),"")) -> 3 | K8: =IF('Portfolio Input'!C8="","",IFERROR(VLOOKUP('Portfolio Input'!C8,'Sector Analysis'!$A$4:$O$15,11,FALSE()),"")) -> 4 | L8: =IF('Portfolio Input'!C8="","",IFERROR(VLOOKUP('Portfolio Input'!C8,'Sector Analysis'!$A$4:$O$15,12,FALSE()),"")) -> 3 | M8: =IF(A8="","",H8*0.25+I8*0.25+J8*0.15+K8*0.2+L8*0.15) -> 2.95 | N8: =IF(A8="","",G8-M8) -> 0.6 | O8: =IF(A8="","",IF(N8<=-2,"CRITICAL",IF(N8<=-0.5,"HIGH",IF(N8<=0.5,"MEDIUM",IF(N8<=1.5,"LOW-MEDIUM","LOW"))))) -> LOW-MEDIUM | P8: =IF(A8="","",IF(G8>=4,22,IF(G8>=3.5,18,IF(G8>=3,14,IF(G8>=2.5,10,IF(G8>=2,7,4)))))) -> 18 | Q8: =IF(A8="","",MAX(2,ROUND(P8*(1-MAX(0,(M8-1.5)*0.15)),0))) -> 14 | R8: =IF(A8="","",MIN(400,IF(M8>=4,300,IF(M8>=3.5,225,IF(M8>=3,150,IF(M8>=2.5,100,IF(M8>=2,50,0))))))) -> 100 | S8: =IF(A8="","",IF('Portfolio Input'!U8<=0.02,30,MIN(50,MAX(5,(1/('Portfolio Input'!U8-0.02))*(1-((1.02)/(1+'Portfolio Input'!U8))^P8)+((1.02)/(1+'Portfolio Input'!U8))^P8*(1/('Portfolio Input'!U8-0.02)))))) -> 7.2339066 | T8: =IF(A8="","",IF(('Portfolio Input'!U8+R8/10000)<=0.02,30,MIN(50,MAX(5,(1/(('Portfolio Input'!U8+R8/10000)-0.02))*(1-((1.02)/(1+('Portfolio Input'!U8+R8/10000)))^Q8)+((1.02)/(1+('Portfolio Input'!U8+R8/10000)))^Q8*(1/(('Portfolio Input'!U8+R8/10000)-0.02)))))) -> 6.7459136 | U8: =IF(A8="","",IF(S8>0,(S8-T8)/S8*100,0)) -> 6.7459136
A9: ='Portfolio Input'!A9 -> AMZN | B9: =IF('Portfolio Input'!C9="","",IFERROR(VLOOKUP('Portfolio Input'!C9,'Sector Analysis'!$A$4:$O$15,2,FALSE()),"")) -> 2 | C9: =IF('Portfolio Input'!C9="","",IFERROR(VLOOKUP('Portfolio Input'!C9,'Sector Analysis'!$A$4:$O$15,3,FALSE()),"")) -> 2 | D9: =IF('Portfolio Input'!C9="","",IFERROR(VLOOKUP('Portfolio Input'!C9,'Sector Analysis'!$A$4:$O$15,4,FALSE()),"")) -> 3 | E9: =IF('Portfolio Input'!C9="","",IFERROR(VLOOKUP('Portfolio Input'!C9,'Sector Analysis'!$A$4:$O$15,5,FALSE()),"")) -> 2 | F9: =IF('Portfolio Input'!C9="","",IFERROR(VLOOKUP('Portfolio Input'!C9,'Sector Analysis'!$A$4:$O$15,6,FALSE()),"")) -> 1 | G9: =IF(A9="","",B9*0.25+C9*0.2+D9*0.25+E9*0.15+F9*0.15) -> 2.1 | H9: =IF('Portfolio Input'!C9="","",IFERROR(VLOOKUP('Portfolio Input'!C9,'Sector Analysis'!$A$4:$O$15,8,FALSE()),"")) -> 3 | I9: =IF('Portfolio Input'!C9="","",IFERROR(VLOOKUP('Portfolio Input'!C9,'Sector Analysis'!$A$4:$O$15,9,FALSE()),"")) -> 4 | J9: =IF('Portfolio Input'!C9="","",IFERROR(VLOOKUP('Portfolio Input'!C9,'Sector Analysis'!$A$4:$O$15,10,FALSE()),"")) -> 3 | K9: =IF('Portfolio Input'!C9="","",IFERROR(VLOOKUP('Portfolio Input'!C9,'Sector Analysis'!$A$4:$O$15,11,FALSE()),"")) -> 3 | L9: =IF('Portfolio Input'!C9="","",IFERROR(VLOOKUP('Portfolio Input'!C9,'Sector Analysis'!$A$4:$O$15,12,FALSE()),"")) -> 3 | M9: =IF(A9="","",H9*0.25+I9*0.25+J9*0.15+K9*0.2+L9*0.15) -> 3.25 | N9: =IF(A9="","",G9-M9) -> -1.15 | O9: =IF(A9="","",IF(N9<=-2,"CRITICAL",IF(N9<=-0.5,"HIGH",IF(N9<=0.5,"MEDIUM",IF(N9<=1.5,"LOW-MEDIUM","LOW"))))) -> HIGH | P9: =IF(A9="","",IF(G9>=4,22,IF(G9>=3.5,18,IF(G9>=3,14,IF(G9>=2.5,10,IF(G9>=2,7,4)))))) -> 7 | Q9: =IF(A9="","",MAX(2,ROUND(P9*(1-MAX(0,(M9-1.5)*0.15)),0))) -> 5 | R9: =IF(A9="","",MIN(400,IF(M9>=4,300,IF(M9>=3.5,225,IF(M9>=3,150,IF(M9>=2.5,100,IF(M9>=2,50,0))))))) -> 150 | S9: =IF(A9="","",IF('Portfolio Input'!U9<=0.02,30,MIN(50,MAX(5,(1/('Portfolio Input'!U9-0.02))*(1-((1.02)/(1+'Portfolio Input'!U9))^P9)+((1.02)/(1+'Portfolio Input'!U9))^P9*(1/('Portfolio Input'!U9-0.02)))))) -> 10.409476 | T9: =IF(A9="","",IF(('Portfolio Input'!U9+R9/10000)<=0.02,30,MIN(50,MAX(5,(1/(('Portfolio Input'!U9+R9/10000)-0.02))*(1-((1.02)/(1+('Portfolio Input'!U9+R9/10000)))^Q9)+((1.02)/(1+('Portfolio Input'!U9+R9/10000)))^Q9*(1/(('Portfolio Input'!U9+R9/10000)-0.02)))))) -> 9.0036303 | U9: =IF(A9="","",IF(S9>0,(S9-T9)/S9*100,0)) -> 13.505445
A10: ='Portfolio Input'!A10 -> META | B10: =IF('Portfolio Input'!C10="","",IFERROR(VLOOKUP('Portfolio Input'!C10,'Sector Analysis'!$A$4:$O$15,2,FALSE()),"")) -> 3 | C10: =IF('Portfolio Input'!C10="","",IFERROR(VLOOKUP('Portfolio Input'!C10,'Sector Analysis'!$A$4:$O$15,3,FALSE()),"")) -> 5 | D10: =IF('Portfolio Input'!C10="","",IFERROR(VLOOKUP('Portfolio Input'!C10,'Sector Analysis'!$A$4:$O$15,4,FALSE()),"")) -> 4 | E10: =IF('Portfolio Input'!C10="","",IFERROR(VLOOKUP('Portfolio Input'!C10,'Sector Analysis'!$A$4:$O$15,5,FALSE()),"")) -> 2 | F10: =IF('Portfolio Input'!C10="","",IFERROR(VLOOKUP('Portfolio Input'!C10,'Sector Analysis'!$A$4:$O$15,6,FALSE()),"")) -> 3 | G10: =IF(A10="","",B10*0.25+C10*0.2+D10*0.25+E10*0.15+F10*0.15) -> 3.5 | H10: =IF('Portfolio Input'!C10="","",IFERROR(VLOOKUP('Portfolio Input'!C10,'Sector Analysis'!$A$4:$O$15,8,FALSE()),"")) -> 3 | I10: =IF('Portfolio Input'!C10="","",IFERROR(VLOOKUP('Portfolio Input'!C10,'Sector Analysis'!$A$4:$O$15,9,FALSE()),"")) -> 3 | J10: =IF('Portfolio Input'!C10="","",IFERROR(VLOOKUP('Portfolio Input'!C10,'Sector Analysis'!$A$4:$O$15,10,FALSE()),"")) -> 4 | K10: =IF('Portfolio Input'!C10="","",IFERROR(VLOOKUP('Portfolio Input'!C10,'Sector Analysis'!$A$4:$O$15,11,FALSE()),"")) -> 3 | L10: =IF('Portfolio Input'!C10="","",IFERROR(VLOOKUP('Portfolio Input'!C10,'Sector Analysis'!$A$4:$O$15,12,FALSE()),"")) -> 4 | M10: =IF(A10="","",H10*0.25+I10*0.25+J10*0.15+K10*0.2+L10*0.15) -> 3.3 | N10: =IF(A10="","",G10-M10) -> 0.2 | O10: =IF(A10="","",IF(N10<=-2,"CRITICAL",IF(N10<=-0.5,"HIGH",IF(N10<=0.5,"MEDIUM",IF(N10<=1.5,"LOW-MEDIUM","LOW"))))) -> MEDIUM | P10: =IF(A10="","",IF(G10>=4,22,IF(G10>=3.5,18,IF(G10>=3,14,IF(G10>=2.5,10,IF(G10>=2,7,4)))))) -> 18 | Q10: =IF(A10="","",MAX(2,ROUND(P10*(1-MAX(0,(M10-1.5)*0.15)),0))) -> 13 | R10: =IF(A10="","",MIN(400,IF(M10>=4,300,IF(M10>=3.5,225,IF(M10>=3,150,IF(M10>=2.5,100,IF(M10>=2,50,0))))))) -> 150 | S10: =IF(A10="","",IF('Portfolio Input'!U10<=0.02,30,MIN(50,MAX(5,(1/('Portfolio Input'!U10-0.02))*(1-((1.02)/(1+'Portfolio Input'!U10))^P10)+((1.02)/(1+'Portfolio Input'!U10))^P10*(1/('Portfolio Input'!U10-0.02)))))) -> 11.192864 | T10: =IF(A10="","",IF(('Portfolio Input'!U10+R10/10000)<=0.02,30,MIN(50,MAX(5,(1/(('Portfolio Input'!U10+R10/10000)-0.02))*(1-((1.02)/(1+('Portfolio Input'!U10+R10/10000)))^Q10)+((1.02)/(1+('Portfolio Input'!U10+R10/10000)))^Q10*(1/(('Portfolio Input'!U10+R10/10000)-0.02)))))) -> 9.5838097 | U10: =IF(A10="","",IF(S10>0,(S10-T10)/S10*100,0)) -> 14.375714
A11: ='Portfolio Input'!A11 -> V | B11: =IF('Portfolio Input'!C11="","",IFERROR(VLOOKUP('Portfolio Input'!C11,'Sector Analysis'!$A$4:$O$15,2,FALSE()),"")) -> 3 | C11: =IF('Portfolio Input'!C11="","",IFERROR(VLOOKUP('Portfolio Input'!C11,'Sector Analysis'!$A$4:$O$15,3,FALSE()),"")) -> 2 | D11: =IF('Portfolio Input'!C11="","",IFERROR(VLOOKUP('Portfolio Input'!C11,'Sector Analysis'!$A$4:$O$15,4,FALSE()),"")) -> 3 | E11: =IF('Portfolio Input'!C11="","",IFERROR(VLOOKUP('Portfolio Input'!C11,'Sector Analysis'!$A$4:$O$15,5,FALSE()),"")) -> 3 | F11: =IF('Portfolio Input'!C11="","",IFERROR(VLOOKUP('Portfolio Input'!C11,'Sector Analysis'!$A$4:$O$15,6,FALSE()),"")) -> 3 | G11: =IF(A11="","",B11*0.25+C11*0.2+D11*0.25+E11*0.15+F11*0.15) -> 2.8 | H11: =IF('Portfolio Input'!C11="","",IFERROR(VLOOKUP('Portfolio Input'!C11,'Sector Analysis'!$A$4:$O$15,8,FALSE()),"")) -> 5 | I11: =IF('Portfolio Input'!C11="","",IFERROR(VLOOKUP('Portfolio Input'!C11,'Sector Analysis'!$A$4:$O$15,9,FALSE()),"")) -> 4 | J11: =IF('Portfolio Input'!C11="","",IFERROR(VLOOKUP('Portfolio Input'!C11,'Sector Analysis'!$A$4:$O$15,10,FALSE()),"")) -> 3 | K11: =IF('Portfolio Input'!C11="","",IFERROR(VLOOKUP('Portfolio Input'!C11,'Sector Analysis'!$A$4:$O$15,11,FALSE()),"")) -> 4 | L11: =IF('Portfolio Input'!C11="","",IFERROR(VLOOKUP('Portfolio Input'!C11,'Sector Analysis'!$A$4:$O$15,12,FALSE()),"")) -> 4 | M11: =IF(A11="","",H11*0.25+I11*0.25+J11*0.15+K11*0.2+L11*0.15) -> 4.1 | N11: =IF(A11="","",G11-M11) -> -1.3 | O11: =IF(A11="","",IF(N11<=-2,"CRITICAL",IF(N11<=-0.5,"HIGH",IF(N11<=0.5,"MEDIUM",IF(N11<=1.5,"LOW-MEDIUM","LOW"))))) -> HIGH | P11: =IF(A11="","",IF(G11>=4,22,IF(G11>=3.5,18,IF(G11>=3,14,IF(G11>=2.5,10,IF(G11>=2,7,4)))))) -> 10 | Q11: =IF(A11="","",MAX(2,ROUND(P11*(1-MAX(0,(M11-1.5)*0.15)),0))) -> 6 | R11: =IF(A11="","",MIN(400,IF(M11>=4,300,IF(M11>=3.5,225,IF(M11>=3,150,IF(M11>=2.5,100,IF(M11>=2,50,0))))))) -> 300 | S11: =IF(A11="","",IF('Portfolio Input'!U11<=0.02,30,MIN(50,MAX(5,(1/('Portfolio Input'!U11-0.02))*(1-((1.02)/(1+'Portfolio Input'!U11))^P11)+((1.02)/(1+'Portfolio Input'!U11))^P11*(1/('Portfolio Input'!U11-0.02)))))) -> 15.920202 | T11: =IF(A11="","",IF(('Portfolio Input'!U11+R11/10000)<=0.02,30,MIN(50,MAX(5,(1/(('Portfolio Input'!U11+R11/10000)-0.02))*(1-((1.02)/(1+('Portfolio Input'!U11+R11/10000)))^Q11)+((1.02)/(1+('Portfolio Input'!U11+R11/10000)))^Q11*(1/(('Portfolio Input'!U11+R11/10000)-0.02)))))) -> 10.774321 | U11: =IF(A11="","",IF(S11>0,(S11-T11)/S11*100,0)) -> 32.322964
A12: ='Portfolio Input'!A12 -> MA | B12: =IF('Portfolio Input'!C12="","",IFERROR(VLOOKUP('Portfolio Input'!C12,'Sector Analysis'!$A$4:$O$15,2,FALSE()),"")) -> 3 | C12: =IF('Portfolio Input'!C12="","",IFERROR(VLOOKUP('Portfolio Input'!C12,'Sector Analysis'!$A$4:$O$15,3,FALSE()),"")) -> 2 | D12: =IF('Portfolio Input'!C12="","",IFERROR(VLOOKUP('Portfolio Input'!C12,'Sector Analysis'!$A$4:$O$15,4,FALSE()),"")) -> 3 | E12: =IF('Portfolio Input'!C12="","",IFERROR(VLOOKUP('Portfolio Input'!C12,'Sector Analysis'!$A$4:$O$15,5,FALSE()),"")) -> 3 | F12: =IF('Portfolio Input'!C12="","",IFERROR(VLOOKUP('Portfolio Input'!C12,'Sector Analysis'!$A$4:$O$15,6,FALSE()),"")) -> 3 | G12: =IF(A12="","",B12*0.25+C12*0.2+D12*0.25+E12*0.15+F12*0.15) -> 2.8 | H12: =IF('Portfolio Input'!C12="","",IFERROR(VLOOKUP('Portfolio Input'!C12,'Sector Analysis'!$A$4:$O$15,8,FALSE()),"")) -> 5 | I12: =IF('Portfolio Input'!C12="","",IFERROR(VLOOKUP('Portfolio Input'!C12,'Sector Analysis'!$A$4:$O$15,9,FALSE()),"")) -> 4 | J12: =IF('Portfolio Input'!C12="","",IFERROR(VLOOKUP('Portfolio Input'!C12,'Sector Analysis'!$A$4:$O$15,10,FALSE()),"")) -> 3 | K12: =IF('Portfolio Input'!C12="","",IFERROR(VLOOKUP('Portfolio Input'!C12,'Sector Analysis'!$A$4:$O$15,11,FALSE()),"")) -> 4 | L12: =IF('Portfolio Input'!C12="","",IFERROR(VLOOKUP('Portfolio Input'!C12,'Sector Analysis'!$A$4:$O$15,12,FALSE()),"")) -> 4 | M12: =IF(A12="","",H12*0.25+I12*0.25+J12*0.15+K12*0.2+L12*0.15) -> 4.1 | N12: =IF(A12="","",G12-M12) -> -1.3 | O12: =IF(A12="","",IF(N12<=-2,"CRITICAL",IF(N12<=-0.5,"HIGH",IF(N12<=0.5,"MEDIUM",IF(N12<=1.5,"LOW-MEDIUM","LOW"))))) -> HIGH | P12: =IF(A12="","",IF(G12>=4,22,IF(G12>=3.5,18,IF(G12>=3,14,IF(G12>=2.5,10,IF(G12>=2,7,4)))))) -> 10 | Q12: =IF(A12="","",MAX(2,ROUND(P12*(1-MAX(0,(M12-1.5)*0.15)),0))) -> 6 | R12: =IF(A12="","",MIN(400,IF(M12>=4,300,IF(M12>=3.5,225,IF(M12>=3,150,IF(M12>=2.5,100,IF(M12>=2,50,0))))))) -> 300 | S12: =IF(A12="","",IF('Portfolio Input'!U12<=0.02,30,MIN(50,MAX(5,(1/('Portfolio Input'!U12-0.02))*(1-((1.02)/(1+'Portfolio Input'!U12))^P12)+((1.02)/(1+'Portfolio Input'!U12))^P12*(1/('Portfolio Input'!U12-0.02)))))) -> 15.560357 | T12: =IF(A12="","",IF(('Portfolio Input'!U12+R12/10000)<=0.02,30,MIN(50,MAX(5,(1/(('Portfolio Input'!U12+R12/10000)-0.02))*(1-((1.02)/(1+('Portfolio Input'!U12+R12/10000)))^Q12)+((1.02)/(1+('Portfolio Input'!U12+R12/10000)))^Q12*(1/(('Portfolio Input'!U12+R12/10000)-0.02)))))) -> 10.608293 | U12: =IF(A12="","",IF(S12>0,(S12-T12)/S12*100,0)) -> 31.824878
